[2022-09-28 17:53:35,985] {taskinstance.py:1179} INFO - Dependencies all met for <TaskInstance: 1_init_once_seed_data.load_seed_data_once manual__2022-09-28T17:53:34.436824+00:00 [queued]>
[2022-09-28 17:53:36,004] {taskinstance.py:1179} INFO - Dependencies all met for <TaskInstance: 1_init_once_seed_data.load_seed_data_once manual__2022-09-28T17:53:34.436824+00:00 [queued]>
[2022-09-28 17:53:36,006] {taskinstance.py:1376} INFO - 
--------------------------------------------------------------------------------
[2022-09-28 17:53:36,008] {taskinstance.py:1377} INFO - Starting attempt 1 of 1
[2022-09-28 17:53:36,010] {taskinstance.py:1378} INFO - 
--------------------------------------------------------------------------------
[2022-09-28 17:53:36,032] {taskinstance.py:1397} INFO - Executing <Task(BashOperator): load_seed_data_once> on 2022-09-28 17:53:34.436824+00:00
[2022-09-28 17:53:36,038] {standard_task_runner.py:52} INFO - Started process 462 to run task
[2022-09-28 17:53:36,045] {standard_task_runner.py:79} INFO - Running: ['***', 'tasks', 'run', '1_init_once_seed_data', 'load_seed_data_once', 'manual__2022-09-28T17:53:34.436824+00:00', '--job-id', '4', '--raw', '--subdir', 'DAGS_FOLDER/init.py', '--cfg-path', '/tmp/tmpeegsv26x', '--error-file', '/tmp/tmp3kq6tc56']
[2022-09-28 17:53:36,047] {standard_task_runner.py:80} INFO - Job 4: Subtask load_seed_data_once
[2022-09-28 17:53:36,202] {task_command.py:371} INFO - Running <TaskInstance: 1_init_once_seed_data.load_seed_data_once manual__2022-09-28T17:53:34.436824+00:00 [running]> on host d5e4932215e1
[2022-09-28 17:53:36,469] {taskinstance.py:1591} INFO - Exporting the following env vars:
AIRFLOW_CTX_DAG_OWNER=***
AIRFLOW_CTX_DAG_ID=1_init_once_seed_data
AIRFLOW_CTX_TASK_ID=load_seed_data_once
AIRFLOW_CTX_EXECUTION_DATE=2022-09-28T17:53:34.436824+00:00
AIRFLOW_CTX_TRY_NUMBER=1
AIRFLOW_CTX_DAG_RUN_ID=manual__2022-09-28T17:53:34.436824+00:00
[2022-09-28 17:53:36,473] {subprocess.py:62} INFO - Tmp dir root location: 
 /tmp
[2022-09-28 17:53:36,479] {subprocess.py:74} INFO - Running command: ['bash', '-c', 'cd /dbt && dbt seed --profiles-dir .']
[2022-09-28 17:53:36,508] {subprocess.py:85} INFO - Output:
[2022-09-28 17:53:41,322] {subprocess.py:92} INFO - [0m17:53:41  Running with dbt=1.2.1
[2022-09-28 17:53:41,715] {subprocess.py:92} INFO - [0m17:53:41  Found 5 models, 0 tests, 0 snapshots, 0 analyses, 506 macros, 0 operations, 3 seed files, 0 sources, 0 exposures, 0 metrics
[2022-09-28 17:53:41,721] {subprocess.py:92} INFO - [0m17:53:41
[2022-09-28 17:53:48,128] {subprocess.py:92} INFO - [0m17:53:48  Concurrency: 1 threads (target='dev')
[2022-09-28 17:53:48,133] {subprocess.py:92} INFO - [0m17:53:48
[2022-09-28 17:53:48,148] {subprocess.py:92} INFO - [0m17:53:48  1 of 3 START seed file PUBLIC.bookings_1 ....................................... [RUN]
[2022-09-28 17:53:49,757] {subprocess.py:92} INFO - [0m17:53:49  [31mUnhandled error while executing seed.dbt_airlfow.bookings_1[0m
[2022-09-28 17:53:49,758] {subprocess.py:92} INFO - [Errno 2] No such file or directory: '/Users/davidthomas/dbt+airlfow+demo/dbt_***_snowflake/demo/dbt/seeds/bookings_1.csv'
[2022-09-28 17:53:49,766] {subprocess.py:92} INFO - [0m17:53:49  1 of 3 ERROR loading seed file PUBLIC.bookings_1 ............................... [[31mERROR[0m in 1.61s]
[2022-09-28 17:53:49,773] {subprocess.py:92} INFO - [0m17:53:49  2 of 3 START seed file PUBLIC.bookings_2 ....................................... [RUN]
[2022-09-28 17:53:51,462] {subprocess.py:92} INFO - [0m17:53:51  [31mUnhandled error while executing seed.dbt_airlfow.bookings_2[0m
[2022-09-28 17:53:51,463] {subprocess.py:92} INFO - [Errno 2] No such file or directory: '/Users/davidthomas/dbt+airlfow+demo/dbt_***_snowflake/demo/dbt/seeds/bookings_2.csv'
[2022-09-28 17:53:51,469] {subprocess.py:92} INFO - [0m17:53:51  2 of 3 ERROR loading seed file PUBLIC.bookings_2 ............................... [[31mERROR[0m in 1.69s]
[2022-09-28 17:53:51,476] {subprocess.py:92} INFO - [0m17:53:51  3 of 3 START seed file PUBLIC.customers ........................................ [RUN]
[2022-09-28 17:53:53,880] {subprocess.py:92} INFO - [0m17:53:53  [31mUnhandled error while executing seed.dbt_airlfow.customers[0m
[2022-09-28 17:53:53,882] {subprocess.py:92} INFO - [Errno 2] No such file or directory: '/Users/davidthomas/dbt+airlfow+demo/dbt_***_snowflake/demo/dbt/seeds/customers.csv'
[2022-09-28 17:53:53,890] {subprocess.py:92} INFO - [0m17:53:53  3 of 3 ERROR loading seed file PUBLIC.customers ................................ [[31mERROR[0m in 2.41s]
[2022-09-28 17:53:53,939] {subprocess.py:92} INFO - [0m17:53:53
[2022-09-28 17:53:53,941] {subprocess.py:92} INFO - [0m17:53:53  Finished running 3 seeds in 0 hours 0 minutes and 12.21 seconds (12.21s).
[2022-09-28 17:53:54,049] {subprocess.py:92} INFO - [0m17:53:54
[2022-09-28 17:53:54,052] {subprocess.py:92} INFO - [0m17:53:54  [31mCompleted with 3 errors and 0 warnings:[0m
[2022-09-28 17:53:54,054] {subprocess.py:92} INFO - [0m17:53:54
[2022-09-28 17:53:54,057] {subprocess.py:92} INFO - [0m17:53:54  [33m[Errno 2] No such file or directory: '/Users/davidthomas/dbt+airlfow+demo/dbt_***_snowflake/demo/dbt/seeds/bookings_1.csv'[0m
[2022-09-28 17:53:54,061] {subprocess.py:92} INFO - [0m17:53:54
[2022-09-28 17:53:54,065] {subprocess.py:92} INFO - [0m17:53:54  [33m[Errno 2] No such file or directory: '/Users/davidthomas/dbt+airlfow+demo/dbt_***_snowflake/demo/dbt/seeds/bookings_2.csv'[0m
[2022-09-28 17:53:54,068] {subprocess.py:92} INFO - [0m17:53:54
[2022-09-28 17:53:54,071] {subprocess.py:92} INFO - [0m17:53:54  [33m[Errno 2] No such file or directory: '/Users/davidthomas/dbt+airlfow+demo/dbt_***_snowflake/demo/dbt/seeds/customers.csv'[0m
[2022-09-28 17:53:54,075] {subprocess.py:92} INFO - [0m17:53:54
[2022-09-28 17:53:54,080] {subprocess.py:92} INFO - [0m17:53:54  Done. PASS=0 WARN=0 ERROR=3 SKIP=0 TOTAL=3
[2022-09-28 17:53:55,120] {subprocess.py:96} INFO - Command exited with return code 1
[2022-09-28 17:53:55,156] {taskinstance.py:1909} ERROR - Task failed with exception
Traceback (most recent call last):
  File "/home/airflow/.local/lib/python3.7/site-packages/airflow/operators/bash.py", line 195, in execute
    f'Bash command failed. The command returned a non-zero exit code {result.exit_code}.'
airflow.exceptions.AirflowException: Bash command failed. The command returned a non-zero exit code 1.
[2022-09-28 17:53:55,166] {taskinstance.py:1420} INFO - Marking task as FAILED. dag_id=1_init_once_seed_data, task_id=load_seed_data_once, execution_date=20220928T175334, start_date=20220928T175335, end_date=20220928T175355
[2022-09-28 17:53:55,195] {standard_task_runner.py:97} ERROR - Failed to execute job 4 for task load_seed_data_once (Bash command failed. The command returned a non-zero exit code 1.; 462)
[2022-09-28 17:53:55,223] {local_task_job.py:156} INFO - Task exited with return code 1
[2022-09-28 17:53:55,297] {local_task_job.py:273} INFO - 0 downstream tasks scheduled from follow-on schedule check
