[2022-09-28 17:28:20,013] {taskinstance.py:1179} INFO - Dependencies all met for <TaskInstance: 1_init_once_seed_data.load_seed_data_once manual__2022-09-28T17:28:16.554150+00:00 [queued]>
[2022-09-28 17:28:20,048] {taskinstance.py:1179} INFO - Dependencies all met for <TaskInstance: 1_init_once_seed_data.load_seed_data_once manual__2022-09-28T17:28:16.554150+00:00 [queued]>
[2022-09-28 17:28:20,049] {taskinstance.py:1376} INFO - 
--------------------------------------------------------------------------------
[2022-09-28 17:28:20,051] {taskinstance.py:1377} INFO - Starting attempt 1 of 1
[2022-09-28 17:28:20,054] {taskinstance.py:1378} INFO - 
--------------------------------------------------------------------------------
[2022-09-28 17:28:20,244] {taskinstance.py:1397} INFO - Executing <Task(BashOperator): load_seed_data_once> on 2022-09-28 17:28:16.554150+00:00
[2022-09-28 17:28:20,402] {standard_task_runner.py:52} INFO - Started process 1133 to run task
[2022-09-28 17:28:20,516] {standard_task_runner.py:79} INFO - Running: ['***', 'tasks', 'run', '1_init_once_seed_data', 'load_seed_data_once', 'manual__2022-09-28T17:28:16.554150+00:00', '--job-id', '5', '--raw', '--subdir', 'DAGS_FOLDER/init.py', '--cfg-path', '/tmp/tmp3uhrtkip', '--error-file', '/tmp/tmps1ei6el9']
[2022-09-28 17:28:20,521] {standard_task_runner.py:80} INFO - Job 5: Subtask load_seed_data_once
[2022-09-28 17:28:21,269] {task_command.py:371} INFO - Running <TaskInstance: 1_init_once_seed_data.load_seed_data_once manual__2022-09-28T17:28:16.554150+00:00 [running]> on host ec50df3269ef
[2022-09-28 17:28:21,970] {taskinstance.py:1591} INFO - Exporting the following env vars:
AIRFLOW_CTX_DAG_OWNER=***
AIRFLOW_CTX_DAG_ID=1_init_once_seed_data
AIRFLOW_CTX_TASK_ID=load_seed_data_once
AIRFLOW_CTX_EXECUTION_DATE=2022-09-28T17:28:16.554150+00:00
AIRFLOW_CTX_TRY_NUMBER=1
AIRFLOW_CTX_DAG_RUN_ID=manual__2022-09-28T17:28:16.554150+00:00
[2022-09-28 17:28:21,974] {subprocess.py:62} INFO - Tmp dir root location: 
 /tmp
[2022-09-28 17:28:21,979] {subprocess.py:74} INFO - Running command: ['bash', '-c', 'cd /dbt && dbt seed --profiles-dir .']
[2022-09-28 17:28:22,114] {subprocess.py:85} INFO - Output:
[2022-09-28 17:28:31,520] {subprocess.py:92} INFO - [0m17:28:31  Running with dbt=1.2.1
[2022-09-28 17:28:32,281] {subprocess.py:92} INFO - [0m17:28:32  Found 5 models, 0 tests, 0 snapshots, 0 analyses, 506 macros, 0 operations, 3 seed files, 0 sources, 0 exposures, 0 metrics
[2022-09-28 17:28:32,287] {subprocess.py:92} INFO - [0m17:28:32
[2022-09-28 17:28:38,669] {subprocess.py:92} INFO - [0m17:28:38  Concurrency: 1 threads (target='dev')
[2022-09-28 17:28:38,672] {subprocess.py:92} INFO - [0m17:28:38
[2022-09-28 17:28:38,688] {subprocess.py:92} INFO - [0m17:28:38  1 of 3 START seed file PUBLIC.bookings_1 ....................................... [RUN]
[2022-09-28 17:28:40,169] {subprocess.py:92} INFO - [0m17:28:40  [31mUnhandled error while executing seed.dbt_airlfow.bookings_1[0m
[2022-09-28 17:28:40,173] {subprocess.py:92} INFO - [Errno 2] No such file or directory: '/Users/davidthomas/dbt+airlfow+demo/dbt_***_snowflake/demo/dbt/seeds/bookings_1.csv'
[2022-09-28 17:28:40,186] {subprocess.py:92} INFO - [0m17:28:40  1 of 3 ERROR loading seed file PUBLIC.bookings_1 ............................... [[31mERROR[0m in 1.49s]
[2022-09-28 17:28:40,201] {subprocess.py:92} INFO - [0m17:28:40  2 of 3 START seed file PUBLIC.bookings_2 ....................................... [RUN]
[2022-09-28 17:28:42,209] {subprocess.py:92} INFO - [0m17:28:42  [31mUnhandled error while executing seed.dbt_airlfow.bookings_2[0m
[2022-09-28 17:28:42,209] {subprocess.py:92} INFO - [Errno 2] No such file or directory: '/Users/davidthomas/dbt+airlfow+demo/dbt_***_snowflake/demo/dbt/seeds/bookings_2.csv'
[2022-09-28 17:28:42,220] {subprocess.py:92} INFO - [0m17:28:42  2 of 3 ERROR loading seed file PUBLIC.bookings_2 ............................... [[31mERROR[0m in 2.01s]
[2022-09-28 17:28:42,233] {subprocess.py:92} INFO - [0m17:28:42  3 of 3 START seed file PUBLIC.customers ........................................ [RUN]
[2022-09-28 17:28:43,645] {subprocess.py:92} INFO - [0m17:28:43  [31mUnhandled error while executing seed.dbt_airlfow.customers[0m
[2022-09-28 17:28:43,646] {subprocess.py:92} INFO - [Errno 2] No such file or directory: '/Users/davidthomas/dbt+airlfow+demo/dbt_***_snowflake/demo/dbt/seeds/customers.csv'
[2022-09-28 17:28:43,656] {subprocess.py:92} INFO - [0m17:28:43  3 of 3 ERROR loading seed file PUBLIC.customers ................................ [[31mERROR[0m in 1.42s]
[2022-09-28 17:28:43,680] {subprocess.py:92} INFO - [0m17:28:43
[2022-09-28 17:28:43,686] {subprocess.py:92} INFO - [0m17:28:43  Finished running 3 seeds in 0 hours 0 minutes and 11.39 seconds (11.39s).
[2022-09-28 17:28:43,806] {subprocess.py:92} INFO - [0m17:28:43
[2022-09-28 17:28:43,812] {subprocess.py:92} INFO - [0m17:28:43  [31mCompleted with 3 errors and 0 warnings:[0m
[2022-09-28 17:28:43,817] {subprocess.py:92} INFO - [0m17:28:43
[2022-09-28 17:28:43,822] {subprocess.py:92} INFO - [0m17:28:43  [33m[Errno 2] No such file or directory: '/Users/davidthomas/dbt+airlfow+demo/dbt_***_snowflake/demo/dbt/seeds/bookings_1.csv'[0m
[2022-09-28 17:28:43,828] {subprocess.py:92} INFO - [0m17:28:43
[2022-09-28 17:28:43,833] {subprocess.py:92} INFO - [0m17:28:43  [33m[Errno 2] No such file or directory: '/Users/davidthomas/dbt+airlfow+demo/dbt_***_snowflake/demo/dbt/seeds/bookings_2.csv'[0m
[2022-09-28 17:28:43,839] {subprocess.py:92} INFO - [0m17:28:43
[2022-09-28 17:28:43,841] {subprocess.py:92} INFO - [0m17:28:43  [33m[Errno 2] No such file or directory: '/Users/davidthomas/dbt+airlfow+demo/dbt_***_snowflake/demo/dbt/seeds/customers.csv'[0m
[2022-09-28 17:28:43,846] {subprocess.py:92} INFO - [0m17:28:43
[2022-09-28 17:28:43,849] {subprocess.py:92} INFO - [0m17:28:43  Done. PASS=0 WARN=0 ERROR=3 SKIP=0 TOTAL=3
[2022-09-28 17:28:44,802] {subprocess.py:96} INFO - Command exited with return code 1
[2022-09-28 17:28:44,823] {taskinstance.py:1909} ERROR - Task failed with exception
Traceback (most recent call last):
  File "/home/airflow/.local/lib/python3.7/site-packages/airflow/operators/bash.py", line 195, in execute
    f'Bash command failed. The command returned a non-zero exit code {result.exit_code}.'
airflow.exceptions.AirflowException: Bash command failed. The command returned a non-zero exit code 1.
[2022-09-28 17:28:44,829] {taskinstance.py:1420} INFO - Marking task as FAILED. dag_id=1_init_once_seed_data, task_id=load_seed_data_once, execution_date=20220928T172816, start_date=20220928T172820, end_date=20220928T172844
[2022-09-28 17:28:44,844] {standard_task_runner.py:97} ERROR - Failed to execute job 5 for task load_seed_data_once (Bash command failed. The command returned a non-zero exit code 1.; 1133)
[2022-09-28 17:28:44,889] {local_task_job.py:156} INFO - Task exited with return code 1
[2022-09-28 17:28:44,924] {local_task_job.py:273} INFO - 0 downstream tasks scheduled from follow-on schedule check
