[2022-09-28 17:38:09,677] {taskinstance.py:1179} INFO - Dependencies all met for <TaskInstance: 1_init_once_seed_data.load_seed_data_once manual__2022-09-28T17:38:07.585152+00:00 [queued]>
[2022-09-28 17:38:09,697] {taskinstance.py:1179} INFO - Dependencies all met for <TaskInstance: 1_init_once_seed_data.load_seed_data_once manual__2022-09-28T17:38:07.585152+00:00 [queued]>
[2022-09-28 17:38:09,703] {taskinstance.py:1376} INFO - 
--------------------------------------------------------------------------------
[2022-09-28 17:38:09,715] {taskinstance.py:1377} INFO - Starting attempt 1 of 1
[2022-09-28 17:38:09,724] {taskinstance.py:1378} INFO - 
--------------------------------------------------------------------------------
[2022-09-28 17:38:09,772] {taskinstance.py:1397} INFO - Executing <Task(BashOperator): load_seed_data_once> on 2022-09-28 17:38:07.585152+00:00
[2022-09-28 17:38:09,786] {standard_task_runner.py:52} INFO - Started process 202 to run task
[2022-09-28 17:38:09,793] {standard_task_runner.py:79} INFO - Running: ['***', 'tasks', 'run', '1_init_once_seed_data', 'load_seed_data_once', 'manual__2022-09-28T17:38:07.585152+00:00', '--job-id', '3', '--raw', '--subdir', 'DAGS_FOLDER/init.py', '--cfg-path', '/tmp/tmpvjvkyb02', '--error-file', '/tmp/tmpt6m984dc']
[2022-09-28 17:38:09,795] {standard_task_runner.py:80} INFO - Job 3: Subtask load_seed_data_once
[2022-09-28 17:38:09,968] {task_command.py:371} INFO - Running <TaskInstance: 1_init_once_seed_data.load_seed_data_once manual__2022-09-28T17:38:07.585152+00:00 [running]> on host 90f74b91582b
[2022-09-28 17:38:10,354] {taskinstance.py:1591} INFO - Exporting the following env vars:
AIRFLOW_CTX_DAG_OWNER=***
AIRFLOW_CTX_DAG_ID=1_init_once_seed_data
AIRFLOW_CTX_TASK_ID=load_seed_data_once
AIRFLOW_CTX_EXECUTION_DATE=2022-09-28T17:38:07.585152+00:00
AIRFLOW_CTX_TRY_NUMBER=1
AIRFLOW_CTX_DAG_RUN_ID=manual__2022-09-28T17:38:07.585152+00:00
[2022-09-28 17:38:10,360] {subprocess.py:62} INFO - Tmp dir root location: 
 /tmp
[2022-09-28 17:38:10,366] {subprocess.py:74} INFO - Running command: ['bash', '-c', 'cd /dbt && dbt seed --profiles-dir .']
[2022-09-28 17:38:10,420] {subprocess.py:85} INFO - Output:
[2022-09-28 17:38:32,307] {subprocess.py:92} INFO - [0m17:38:32  Running with dbt=1.2.1
[2022-09-28 17:38:33,466] {subprocess.py:92} INFO - [0m17:38:33  Found 5 models, 0 tests, 0 snapshots, 0 analyses, 506 macros, 0 operations, 3 seed files, 0 sources, 0 exposures, 0 metrics
[2022-09-28 17:38:33,478] {subprocess.py:92} INFO - [0m17:38:33
[2022-09-28 17:38:43,079] {subprocess.py:92} INFO - [0m17:38:43  Concurrency: 1 threads (target='dev')
[2022-09-28 17:38:43,084] {subprocess.py:92} INFO - [0m17:38:43
[2022-09-28 17:38:43,116] {subprocess.py:92} INFO - [0m17:38:43  1 of 3 START seed file PUBLIC.bookings_1 ....................................... [RUN]
[2022-09-28 17:38:44,518] {subprocess.py:92} INFO - [0m17:38:44  [31mUnhandled error while executing seed.dbt_airlfow.bookings_1[0m
[2022-09-28 17:38:44,520] {subprocess.py:92} INFO - [Errno 2] No such file or directory: '/Users/davidthomas/dbt+airlfow+demo/dbt_***_snowflake/demo/dbt/seeds/bookings_1.csv'
[2022-09-28 17:38:44,528] {subprocess.py:92} INFO - [0m17:38:44  1 of 3 ERROR loading seed file PUBLIC.bookings_1 ............................... [[31mERROR[0m in 1.41s]
[2022-09-28 17:38:44,535] {subprocess.py:92} INFO - [0m17:38:44  2 of 3 START seed file PUBLIC.bookings_2 ....................................... [RUN]
[2022-09-28 17:38:46,900] {subprocess.py:92} INFO - [0m17:38:46  [31mUnhandled error while executing seed.dbt_airlfow.bookings_2[0m
[2022-09-28 17:38:46,901] {subprocess.py:92} INFO - [Errno 2] No such file or directory: '/Users/davidthomas/dbt+airlfow+demo/dbt_***_snowflake/demo/dbt/seeds/bookings_2.csv'
[2022-09-28 17:38:46,908] {subprocess.py:92} INFO - [0m17:38:46  2 of 3 ERROR loading seed file PUBLIC.bookings_2 ............................... [[31mERROR[0m in 2.37s]
[2022-09-28 17:38:46,916] {subprocess.py:92} INFO - [0m17:38:46  3 of 3 START seed file PUBLIC.customers ........................................ [RUN]
[2022-09-28 17:38:48,302] {subprocess.py:92} INFO - [0m17:38:48  [31mUnhandled error while executing seed.dbt_airlfow.customers[0m
[2022-09-28 17:38:48,304] {subprocess.py:92} INFO - [Errno 2] No such file or directory: '/Users/davidthomas/dbt+airlfow+demo/dbt_***_snowflake/demo/dbt/seeds/customers.csv'
[2022-09-28 17:38:48,309] {subprocess.py:92} INFO - [0m17:38:48  3 of 3 ERROR loading seed file PUBLIC.customers ................................ [[31mERROR[0m in 1.39s]
[2022-09-28 17:38:48,391] {subprocess.py:92} INFO - [0m17:38:48
[2022-09-28 17:38:48,392] {subprocess.py:92} INFO - [0m17:38:48  Finished running 3 seeds in 0 hours 0 minutes and 14.91 seconds (14.91s).
[2022-09-28 17:38:48,502] {subprocess.py:92} INFO - [0m17:38:48
[2022-09-28 17:38:48,504] {subprocess.py:92} INFO - [0m17:38:48  [31mCompleted with 3 errors and 0 warnings:[0m
[2022-09-28 17:38:48,506] {subprocess.py:92} INFO - [0m17:38:48
[2022-09-28 17:38:48,508] {subprocess.py:92} INFO - [0m17:38:48  [33m[Errno 2] No such file or directory: '/Users/davidthomas/dbt+airlfow+demo/dbt_***_snowflake/demo/dbt/seeds/bookings_1.csv'[0m
[2022-09-28 17:38:48,510] {subprocess.py:92} INFO - [0m17:38:48
[2022-09-28 17:38:48,512] {subprocess.py:92} INFO - [0m17:38:48  [33m[Errno 2] No such file or directory: '/Users/davidthomas/dbt+airlfow+demo/dbt_***_snowflake/demo/dbt/seeds/bookings_2.csv'[0m
[2022-09-28 17:38:48,515] {subprocess.py:92} INFO - [0m17:38:48
[2022-09-28 17:38:48,518] {subprocess.py:92} INFO - [0m17:38:48  [33m[Errno 2] No such file or directory: '/Users/davidthomas/dbt+airlfow+demo/dbt_***_snowflake/demo/dbt/seeds/customers.csv'[0m
[2022-09-28 17:38:48,520] {subprocess.py:92} INFO - [0m17:38:48
[2022-09-28 17:38:48,522] {subprocess.py:92} INFO - [0m17:38:48  Done. PASS=0 WARN=0 ERROR=3 SKIP=0 TOTAL=3
[2022-09-28 17:38:49,477] {subprocess.py:96} INFO - Command exited with return code 1
[2022-09-28 17:38:49,519] {taskinstance.py:1909} ERROR - Task failed with exception
Traceback (most recent call last):
  File "/home/airflow/.local/lib/python3.7/site-packages/airflow/operators/bash.py", line 195, in execute
    f'Bash command failed. The command returned a non-zero exit code {result.exit_code}.'
airflow.exceptions.AirflowException: Bash command failed. The command returned a non-zero exit code 1.
[2022-09-28 17:38:49,527] {taskinstance.py:1420} INFO - Marking task as FAILED. dag_id=1_init_once_seed_data, task_id=load_seed_data_once, execution_date=20220928T173807, start_date=20220928T173809, end_date=20220928T173849
[2022-09-28 17:38:49,549] {standard_task_runner.py:97} ERROR - Failed to execute job 3 for task load_seed_data_once (Bash command failed. The command returned a non-zero exit code 1.; 202)
[2022-09-28 17:38:49,565] {local_task_job.py:156} INFO - Task exited with return code 1
[2022-09-28 17:38:49,596] {local_task_job.py:273} INFO - 0 downstream tasks scheduled from follow-on schedule check
